Workbook

Sheet FORMATTING
B1: MODEL FORMATTING STANDARDS — MAZAGON DOCK SHIPBUILDERS LTD
B3: A. FONT STANDARDS
B4: Font Family | C4: Aptos Narrow | D4: All cells throughout model
B5: Font Size | C5: 11pt (body) | 12–13pt (titles) | D5: Titles use larger size
B6: Hardcoded Values | C6: Black (FF000000) | D6: Direct inputs — no formula
B7: Formula Values | C7: Blue (0070C0) | D7: All cells containing = formulas
B8: Section Headers | C8: Black bold on blue fill (BDD7EE) | D8: Section dividers
B9: Title Bars | C9: White on navy (1F4E79) | D9: Sheet title rows
B10: Methodology Notes | C10: Grey (595959) | D10: Italics, small text 9pt
B11: Warning / Flags | C11: Red (CC0000) | D11: Outliers, limitations
B13: B. NUMBER FORMATS
B14: Currency (INR) | C14: \₹#,##0.00;[Red](\₹#,##0.00) | D14: Brackets for negatives (red)
B15: Percentage | C15: 0.0% or 0.00% | D15: No bracket — minus sign standard for %
B16: Multiples | C16: 0.0x | D16: EV/EBITDA, P/E, ratios
B17: Date | C17: m/d/yyyy | D17: Year headers in all 10Y sheets
B18: Shares | C18: 0.000 | D18: In Crore to 3 decimal places
B19: EPS / DPS | C19: #,##0.00 | D19: Per share values
B20: Days | C20: 0 | D20: DIO, DSO, DPO, CCC
B22: C. FILL COLORS (consistent across all sheets + original 6)
B23: Section Headers | C23: #BDD7EE Light Blue | D23: All section divider rows
B24: Total / Summary | C24: #D9D9D9 Light Grey | D24: Subtotal and total rows
B25: Actual Columns | C25: #C6EFCE Light Green | D25: FY21–FY25 historical data
B26: Forecast Columns | C26: #FFEB9C Light Yellow | D26: FY26–FY30 forecast data
B27: Subject Company | C27: #C6EFCE Light Green | D27: MDL row in CCA
B28: Title Bar | C28: #1F4E79 Navy Blue | D28: Sheet title bars
B29: Selected WACC / Key | C29: #D9D9D9 Light Grey | D29: Key output rows
B30: Assumption Highlight | C30: #FAE2D5 Peach/Orange | D30: Highlighted assumption rows in FS/A&R
B31: Row Group Fill | C31: #D8D8D8 Light Grey | D31: Alternating group rows in Forecast Schedules
B32: Reasoning Column | C32: #BFBFBF Medium Grey | D32: Reasoning/notes column fill in A&R sheet
B33: VALUATION ENGINE | C33: #4472C4 Blue | D33: FCF, WACC, DCF, DDM, CCA
B34: OUTPUT / SUMMARY | C34: #70AD47 Green | D34: Sensitivity Analysis, Final Valuation, Key Ratios
B36: E. SHEET ORDER
B37: 1. FORMATTING — This sheet (formatting standards)
B38: 2. INCOME STATEMENT — Revenue, EBITDA, PAT, EPS | FY21–FY30
B39: 3. BALANCE SHEET — Assets, Liabilities, Equity | FY21–FY30
B40: 4. CASH FLOW STATEMENT — Operating, Investing, Financing | FY21–FY30
B41: 5. FORECAST SCHEDULES — 11 supporting schedules (S01–S11)
B42: 6. ASSUMPTIONS AND REASONING — All forecast assumptions with rationale
B43: 7. ORDER BOOK SCHEDULE — Opening, New Orders, Revenue Recognized, Closing
B44: 8. FREE CASH FLOW — FCFF build from NOPAT | FY21–FY30
...

Sheet INCOME STATEMENT
C1: ACTUAL | D1: ACTUAL | E1: ACTUAL | F1: ACTUAL | G1: ACTUAL | H1: FORECASTED | I1: FORECASTED | J1: FORECASTED | K1: FORECASTED | L1: FORECASTED
B2: YEAR | C2: 44286 | D2: 44651 | E2: 45016 | F2: 45382 | G2: 45747 | H2: 46112 | I2: 46477 | J2: 46843 | K2: 47208 | L2: 47573
B3: Ship Construction | C3: 2988.62 | D3: 4340.26 | E3: 6667.72 | F3: 7527.7 | G3: 8385.43 | H3: =G3*(1+'ASSUMPTIONS AND REASONING'!J5) -> 9391.6816 | I3: =H3*(1+'ASSUMPTIONS AND REASONING'!K5) -> 10236.933 | J3: =I3*(1+'ASSUMPTIONS AND REASONING'!L5) -> 11260.626 | K3: =J3*(1+'ASSUMPTIONS AND REASONING'!M5) -> 12837.114 | L3: =K3*(1+'ASSUMPTIONS AND REASONING'!N5) -> 14891.052
B4: Offshore Project | C4: 0 | D4: 0 | E4: 0 | F4: 3.23 | G4: 1009.64 | H4: ='ASSUMPTIONS AND REASONING'!J6 -> 1010 | I4: ='ASSUMPTIONS AND REASONING'!K6 -> 1010 | J4: ='ASSUMPTIONS AND REASONING'!L6 -> 1010 | K4: ='ASSUMPTIONS AND REASONING'!M6 -> 1010 | L4: ='ASSUMPTIONS AND REASONING'!N6 -> 1010
B5: Sale of Base & Depot Spares | C5: 620.33 | D5: 983.67 | E5: 747.64 | F5: 1217.15 | G5: 1228.16 | H5: =G5*(1+'ASSUMPTIONS AND REASONING'!J7) -> 1390.722 | I5: =H5*(1+'ASSUMPTIONS AND REASONING'!K7) -> 1747.3947 | J5: =I5*(1+'ASSUMPTIONS AND REASONING'!L7) -> 1979.1422 | K5: =J5*(1+'ASSUMPTIONS AND REASONING'!M7) -> 2323.1518 | L5: =K5*(1+'ASSUMPTIONS AND REASONING'!N7) -> 2759.0587
B6: Sale of Other Goods | C6: 0 | D6: 0 | E6: 0 | F6: 21.29 | G6: 25.77 | H6: ='ASSUMPTIONS AND REASONING'!J8 -> 25.77 | I6: ='ASSUMPTIONS AND REASONING'!K8 -> 25.77 | J6: ='ASSUMPTIONS AND REASONING'!L8 -> 25.77 | K6: ='ASSUMPTIONS AND REASONING'!M8 -> 25.77 | L6: ='ASSUMPTIONS AND REASONING'!N8 -> 25.77
B7: Ship Repair | C7: 432.63 | D7: 393.68 | E7: 168.67 | F7: 298.64 | G7: 547.04 | H7: ='ASSUMPTIONS AND REASONING'!J9 -> 574 | I7: ='ASSUMPTIONS AND REASONING'!K9 -> 279 | J7: ='ASSUMPTIONS AND REASONING'!L9 -> 196 | K7: ='ASSUMPTIONS AND REASONING'!M9 -> 202 | L7: ='ASSUMPTIONS AND REASONING'!N9 -> 208
B8: Other Operating Revenue | C8: 6.24 | D8: 15.67 | E8: 243.15 | F8: 398.57 | G8: 235.84 | H8: ='ASSUMPTIONS AND REASONING'!J10 -> 292.52 | I8: ='ASSUMPTIONS AND REASONING'!K10 -> 308.97667 | J8: ='ASSUMPTIONS AND REASONING'!L10 -> 279.11222 | K8: ='ASSUMPTIONS AND REASONING'!M10 -> 293.5363 | L8: ='ASSUMPTIONS AND REASONING'!N10 -> 293.87506
B9: Revenue from Operations | C9: =SUM(C3:C8) -> 4047.82 | D9: =SUM(D3:D8) -> 5733.28 | E9: =SUM(E3:E8) -> 7827.18 | F9: =SUM(F3:F8) -> 9466.58 | G9: =SUM(G3:G8) -> 11431.88 | H9: =SUM(H3:H8) -> 12684.694 | I9: =SUM(I3:I8) -> 13608.074 | J9: =SUM(J3:J8) -> 14750.651 | ... L9: =SUM(L3:L8) -> 19187.756
B10: Revenue Growth (YoY %) | D10: =D9/C9-1 -> 0.41638709 | E10: =E9/D9-1 -> 0.36521851 | F10: =F9/E9-1 -> 0.20944964 | G10: =G9/F9-1 -> 0.20760401 | H10: =H9/G9-1 -> 0.10958947 | I10: =I9/H9-1 -> 0.072794871 | J10: =J9/I9-1 -> 0.083963119 | K10: =K9/J9-1 -> 0.13158209 | L10: =L9/K9-1 -> 0.14954756
B12: COGS | C12: 2279.07 | D12: 3122.42 | E12: 4900.93 | F12: 5464.08 | G12: 5851.68 | H12: =SUM(H3,H4,H6,H7)*'ASSUMPTIONS AND REASONING'!J11 -> 7334.0338 | I12: =SUM(I3,I4,I6,I7)*'ASSUMPTIONS AND REASONING'!K11 -> 7507.3781 | J12: =SUM(J3,J4,J6,J7)*'ASSUMPTIONS AND REASONING'!L11 -> 7926.7986 | K12: =SUM(K3,K4,K6,K7)*'ASSUMPTIONS AND REASONING'!M11 -> 9153.6752 | L12: =SUM(L3,L4,L6,L7)*'ASSUMPTIONS AND REASONING'!N11 -> 10405.771
B13: Procurement of Base & Depot Spares | C13: 578.33 | D13: 913.65 | E13: 693.22 | F13: 1145.83 | G13: 1151.64 | H13: =H5*'ASSUMPTIONS AND REASONING'!J12 -> 1300.9326 | I13: =I5*'ASSUMPTIONS AND REASONING'!K12 -> 1639.3686 | J13: =J5*'ASSUMPTIONS AND REASONING'!L12 -> 1854.6614 | K13: =K5*'ASSUMPTIONS AND REASONING'!M12 -> 2176.5758 | L13: =L5*'ASSUMPTIONS AND REASONING'!N12 -> 2586.3314
B15: Salaries, wages, allowances & bonus | C15: 470.21 | D15: 615.9 | E15: 626.03 | F15: 690.19 | G15: 730.25 | H15: ='ASSUMPTIONS AND REASONING'!J14*H21 -> 822.83259 | I15: ='ASSUMPTIONS AND REASONING'!K14*I21 -> 889.78781 | J15: ='ASSUMPTIONS AND REASONING'!L14*J21 -> 966.59091 | K15: ='ASSUMPTIONS AND REASONING'!M14*K21 -> 1061.2229 | L15: ='ASSUMPTIONS AND REASONING'!N14*L21 -> 1155.1361
B16: Pension | C16: 19.16 | D16: 20.83 | E16: 22.36 | F16: 22.95 | G16: 55.74 | H16: ='ASSUMPTIONS AND REASONING'!J15*H21 -> 39.525698 | I16: ='ASSUMPTIONS AND REASONING'!K15*I21 -> 46.53122 | J16: ='ASSUMPTIONS AND REASONING'!L15*J21 -> 56.773065 | K16: ='ASSUMPTIONS AND REASONING'!M15*K21 -> 56.244566 | L16: ='ASSUMPTIONS AND REASONING'!N15*L21 -> 63.152025
B17: Contribution to PF & ESI | C17: 41.99 | D17: 41.6 | E17: 40.53 | F17: 41.94 | G17: 43.47 | H17: ='ASSUMPTIONS AND REASONING'!J16*H21 -> 50.790839 | I17: ='ASSUMPTIONS AND REASONING'!K16*I21 -> 53.996534 | J17: ='ASSUMPTIONS AND REASONING'!L16*J21 -> 58.630782 | K17: ='ASSUMPTIONS AND REASONING'!M16*K21 -> 64.761723 | L17: ='ASSUMPTIONS AND REASONING'!N16*L21 -> 70.220148
B18: Workmen & staff welfare | C18: 73.67 | D18: 83.69 | E18: 68.1 | F18: 98.78 | G18: 97.95 | H18: ='ASSUMPTIONS AND REASONING'!J17*H21 -> 105.69263 | I18: ='ASSUMPTIONS AND REASONING'!K17*I21 -> 120.34308 | J18: ='ASSUMPTIONS AND REASONING'!L17*J21 -> 128.15754 | K18: ='ASSUMPTIONS AND REASONING'!M17*K21 -> 140.17005 | L18: ='ASSUMPTIONS AND REASONING'!N17*L21 -> 153.98742
B19: Gratuity | C19: 20.43 | D19: 8.95 | E19: 9.38 | F19: 10.65 | G19: 12.86 | H19: ='ASSUMPTIONS AND REASONING'!J18*H21 -> 13.151127 | I19: ='ASSUMPTIONS AND REASONING'!K18*I21 -> 14.528677 | J19: ='ASSUMPTIONS AND REASONING'!L18*J21 -> 16.076214 | K19: ='ASSUMPTIONS AND REASONING'!M18*K21 -> 17.311603 | L19: ='ASSUMPTIONS AND REASONING'!N18*L21 -> 18.971969
B20: Encashment of privilege leave | C20: 27.35 | D20: 27.76 | E20: 26.31 | F20: 32.04 | G20: 38.48 | H20: ='ASSUMPTIONS AND REASONING'!J19*H21 -> 38.628886 | I20: ='ASSUMPTIONS AND REASONING'!K19*I21 -> 43.285386 | J20: ='ASSUMPTIONS AND REASONING'!L19*J21 -> 47.748957 | K20: ='ASSUMPTIONS AND REASONING'!M19*K21 -> 51.283856 | L20: ='ASSUMPTIONS AND REASONING'!N19*L21 -> 56.358459
B21: Employee Benefit Expenses | C21: =SUM(C15:C20) -> 652.81 | D21: =SUM(D15:D20) -> 798.73 | E21: =SUM(E15:E20) -> 792.71 | F21: =SUM(F15:F20) -> 896.55 | G21: =SUM(G15:G20) -> 978.75 | H21: =G21*(1+'ASSUMPTIONS AND REASONING'!J13) -> 1070.6218 | I21: =H21*(1+'ASSUMPTIONS AND REASONING'!K13) -> 1168.4727 | J21: =I21*(1+'ASSUMPTIONS AND REASONING'!L13) -> 1273.9775 | K21: =J21*(1+'ASSUMPTIONS AND REASONING'!M13) -> 1390.9947 | L21: =K21*(1+'ASSUMPTIONS AND REASONING'!N13) -> 1517.8261
B23: Power & Fuel | C23: 11.37 | D23: 14.73 | E23: 16.46 | F23: 17.69 | G23: 19.65 | H23: =H9*'ASSUMPTIONS AND REASONING'!J20 -> 24.060686 | I23: =I9*'ASSUMPTIONS AND REASONING'!K20 -> 24.877305 | J23: =J9*'ASSUMPTIONS AND REASONING'!L20 -> 26.766698 | K23: =K9*'ASSUMPTIONS AND REASONING'!M20 -> 30.821366 | L23: =L9*'ASSUMPTIONS AND REASONING'!N20 -> 35.108874
B24: Other Expenses — Project Related | C24: 168.35 | D24: 164.34 | E24: 288.75 | F24: 166.82 | G24: 299.62 | H24: =H12*'ASSUMPTIONS AND REASONING'!J21 -> 343.84414 | I24: =I12*'ASSUMPTIONS AND REASONING'!K21 -> 321.85644 | J24: =J12*'ASSUMPTIONS AND REASONING'!L21 -> 372.44794 | K24: =K12*'ASSUMPTIONS AND REASONING'!M21 -> 417.22848 | L24: =L12*'ASSUMPTIONS AND REASONING'!N21 -> 469.7802
B25: Other Expenses | C25: 114.2 | D25: 182.16 | E25: 219.92 | F25: 195.5 | G25: 323.77 | H25: =H9*'ASSUMPTIONS AND REASONING'!J22 -> 325.87079 | I25: =I9*'ASSUMPTIONS AND REASONING'!K22 -> 338.67482 | J25: =J9*'ASSUMPTIONS AND REASONING'!L22 -> 387.93985 | K25: =K9*'ASSUMPTIONS AND REASONING'!M22 -> 427.73661 | L25: =L9*'ASSUMPTIONS AND REASONING'!N22 -> 491.29311
B26: Provisions | C26: 19.82 | D26: 102.55 | E26: 117.39 | F26: 168.5 | G26: 746.75 | H26: ='ASSUMPTIONS AND REASONING'!J23 -> 468 | I26: ='ASSUMPTIONS AND REASONING'!K23 -> 165 | J26: ='ASSUMPTIONS AND REASONING'!L23 -> 178.85391 | K26: ='ASSUMPTIONS AND REASONING'!M23 -> 202.38789 | L26: ='ASSUMPTIONS AND REASONING'!N23 -> 232.6545
B27: Total Operating Expenses (excl. D&A) | C27: =SUM(C21:C26,C12:C13) -> 3823.95 | D27: =SUM(D21:D26,D12:D13) -> 5298.58 | E27: =SUM(E21:E26,E12:E13) -> 7029.38 | F27: =SUM(F21:F26,F12:F13) -> 8054.97 | G27: =SUM(G21:G26,G12:G13) -> 9371.86 | H27: =SUM(H21:H26,H12:H13) -> 10867.364 | I27: =SUM(I21:I26,I12:I13) -> 11165.628 | J27: =SUM(J21:J26,J12:J13) -> 12021.446 | ... L27: =SUM(L21:L26,L12:L13) -> 15738.765
B29: EBITDA | C29: =C9-C27 -> 223.87 | D29: =D9-D27 -> 434.7 | E29: =E9-E27 -> 797.8 | F29: =F9-F27 -> 1411.61 | G29: =G9-G27 -> 2060.02 | H29: =H9-H27 -> 1817.3299 | I29: =I9-I27 -> 2442.4463 | J29: =J9-J27 -> 2729.2048 | ... L29: =L9-L27 -> 3448.9911
B31: PP&E D&A (ex-ROU) | D31: 63.19 | E31: 56.97 | F31: 63.82 | G31: 84.28 | H31: ='FORECAST SCHEDULES'!I38 -> 72.633677 | I31: ='FORECAST SCHEDULES'!J38 -> 76.923083 | J31: ='FORECAST SCHEDULES'!K38 -> 81.508704 | K31: ='FORECAST SCHEDULES'!L38 -> 79.913578 | L31: ='FORECAST SCHEDULES'!M38 -> 81.678967
B32: ROU D&A | D32: 5.5 | E32: 14.21 | F32: 13.94 | G32: 23.97 | H32: =-'FORECAST SCHEDULES'!I55 -> 22.59 | I32: =-'FORECAST SCHEDULES'!J55 -> 22.59 | J32: =-'FORECAST SCHEDULES'!K55 -> 22.59 | K32: =-'FORECAST SCHEDULES'!L55 -> 22.59 | L32: =-'FORECAST SCHEDULES'!M55 -> 22.59
B33: Intangibles Amortization | D33: 5.82 | E33: 4.4 | F33: 5.37 | G33: 6.94 | H33: ='ASSUMPTIONS AND REASONING'!J29 -> 5.57 | I33: ='ASSUMPTIONS AND REASONING'!K29 -> 5.96 | J33: ='ASSUMPTIONS AND REASONING'!L29 -> 6.1566667 | K33: ='ASSUMPTIONS AND REASONING'!M29 -> 5.8955556 | L33: ='ASSUMPTIONS AND REASONING'!N29 -> 6.0040741
B34: Depreciation & Amortization | C34: 59.65 | D34: =SUM(D31:D33) -> 74.51 | E34: =SUM(E31:E33) -> 75.58 | F34: =SUM(F31:F33) -> 83.13 | G34: =SUM(G31:G33) -> 115.19 | H34: =SUM(H31:H33) -> 100.79368 | I34: =SUM(I31:I33) -> 105.47308 | J34: =SUM(J31:J33) -> 110.25537 | K34: =SUM(K31:K33) -> 108.39913 | L34: =SUM(L31:L33) -> 110.27304
B36: EBIT / Operating Income | C36: =C29-C34 -> 164.22 | D36: =D29-D34 -> 360.19 | E36: =E29-E34 -> 722.22 | F36: =F29-F34 -> 1328.48 | G36: =G29-G34 -> 1944.83 | H36: =H29-H34 -> 1716.5362 | I36: =I29-I34 -> 2336.9732 | J36: =J29-J34 -> 2618.9494 | ... L36: =L29-L34 -> 3338.7181
B38: Interest on Lease Liability | C38: 4.55 | D38: 3.1 | E38: 1.55 | F38: 0.75 | G38: 0.07 | H38: ='FORECAST SCHEDULES'!I44 -> 1 | I38: ='FORECAST SCHEDULES'!J44 -> 1 | J38: ='FORECAST SCHEDULES'!K44 -> 1 | K38: ='FORECAST SCHEDULES'!L44 -> 1 | L38: ='FORECAST SCHEDULES'!M44 -> 1
B39: Interest on Deferred Foreign Payment | C39: 3.71 | D39: 3.98 | E39: 4.74 | F39: 4.33 | G39: 4.27 | H39: ='FORECAST SCHEDULES'!I237 -> 4.4597137 | I39: ='FORECAST SCHEDULES'!J237 -> 4.353149 | J39: ='FORECAST SCHEDULES'!K237 -> 4.3608543 | K39: ='FORECAST SCHEDULES'!L237 -> 4.3912087 | L39: ='FORECAST SCHEDULES'!M237 -> 4.3684011
B40: Interest on Deferred Vendor Deposits | C40: 0.1 | D40: 0.08 | E40: 0.06 | F40: 0.04 | G40: 0.06 | H40: ='FORECAST SCHEDULES'!I244 -> 0.052642234 | I40: ='FORECAST SCHEDULES'!J244 -> 0.051037314 | J40: ='FORECAST SCHEDULES'!K244 -> 0.054584367 | K40: ='FORECAST SCHEDULES'!L244 -> 0.052760253 | L40: ='FORECAST SCHEDULES'!M244 -> 0.052799493
B41: Others | C41: 0 | D41: 0 | E41: 0.02 | F41: 0 | G41: 0 | H41: 0 | I41: 0 | J41: 0 | K41: 0 | L41: 0
B42: Interest Expense | C42: =-SUM(C38:C41) -> -8.36 | D42: =-SUM(D38:D41) -> -7.16 | E42: =-SUM(E38:E41) -> -6.37 | F42: =-SUM(F38:F41) -> -5.12 | G42: =-SUM(G38:G41) -> -4.4 | H42: =-SUM(H38:H41) -> -5.5123559 | I42: =-SUM(I38:I41) -> -5.4041863 | J42: =-SUM(J38:J41) -> -5.4154387 | ... L42: =-SUM(L38:L41) -> -5.4212005
B44: Interest & Investment Income | C44: 368.24 | D44: 347.48 | E44: 601.77 | F44: 994.41 | G44: 1005.84 | H44: ='FORECAST SCHEDULES'!I225 -> 794.57043 | I44: ='FORECAST SCHEDULES'!J225 -> 758.51234 | J44: ='FORECAST SCHEDULES'!K225 -> 1460.3229 | K44: ='FORECAST SCHEDULES'!L225 -> 2248.1382 | L44: ='FORECAST SCHEDULES'!M225 -> 2895.4462
B45: Earnings From Equity Investments | C45: 26.1 | D45: 23.36 | E45: 26.65 | F45: 36.55 | G45: 47.54 | H45: ='FORECAST SCHEDULES'!I147 -> 50 | I45: ='FORECAST SCHEDULES'!J147 -> 50 | J45: ='FORECAST SCHEDULES'!K147 -> 50 | K45: ='FORECAST SCHEDULES'!L147 -> 50 | L45: ='FORECAST SCHEDULES'!M147 -> 50
B46: Currency Exchange Gain (Loss) | C46: 0.01 | D46: 0 | E46: 0.21 | F46: 0 | G46: 0 | H46: ='ASSUMPTIONS AND REASONING'!J24 -> 0 | I46: ='ASSUMPTIONS AND REASONING'!K24 -> 0 | J46: ='ASSUMPTIONS AND REASONING'!L24 -> 0 | K46: ='ASSUMPTIONS AND REASONING'!M24 -> 0 | L46: ='ASSUMPTIONS AND REASONING'!N24 -> 0
B47: Other Non-Operating Income (Expenses) | C47: 205.81 | D47: 61.78 | E47: 83.95 | F47: 105.58 | G47: 114.6 | H47: =H9*'ASSUMPTIONS AND REASONING'!J25 -> 134.89311 | I47: =I9*'ASSUMPTIONS AND REASONING'!K25 -> 144.29928 | J47: =J9*'ASSUMPTIONS AND REASONING'!L25 -> 153.71587 | K47: =K9*'ASSUMPTIONS AND REASONING'!M25 -> 176.1474 | L47: =L9*'ASSUMPTIONS AND REASONING'!N25 -> 201.97016
B48: EBT Excluding Unusual Items | C48: =C36+SUM(C44:C47)+C42 -> 756.02 | D48: =D36+SUM(D44:D47)+D42 -> 785.65 | E48: =E36+SUM(E44:E47)+E42 -> 1428.43 | F48: =F36+SUM(F44:F47)+F42 -> 2459.9 | G48: =G36+SUM(G44:G47)+G42 -> 3108.41 | H48: =H36+SUM(H44:H47)+H42 -> 2690.4874 | I48: =I36+SUM(I44:I47)+I42 -> 3284.3806 | J48: =J36+SUM(J44:J47)+J42 -> 4277.5728 | ... L48: =L36+SUM(L44:L47)+L42 -> 6480.7133
...

Sheet BALANCE SHEET
C1: ACTUAL | D1: ACTUAL | E1: ACTUAL | F1: ACTUAL | G1: ACTUAL | H1: FORECASTED | I1: FORECASTED | J1: FORECASTED | K1: FORECASTED | L1: FORECASTED
B2: YEAR | C2: 44286 | D2: 44651 | E2: 45016 | F2: 45382 | G2: 45747 | H2: 46112 | I2: 46477 | J2: 46843 | K2: 47208 | L2: 47573
B3: ASSETS
B4: Non-current assets
B5: Property, Plant and Equipment | C5: 794.93 | D5: 713.54 | E5: 777.63 | F5: 780.3 | G5: 773.94 | H5: ='FORECAST SCHEDULES'!I5 -> 755.44952 | I5: ='FORECAST SCHEDULES'!J5 -> 738.30701 | J5: ='FORECAST SCHEDULES'!K5 -> 731.58782 | K5: ='FORECAST SCHEDULES'!L5 -> 691.46201 | L5: ='FORECAST SCHEDULES'!M5 -> 649.56899
B6: Right-of-Use Assets | C6: 0 | D6: 243.02 | E6: 229.34 | F6: 39.35 | G6: 670.38 | H6: ='FORECAST SCHEDULES'!I57 -> 654.79 | I6: ='FORECAST SCHEDULES'!J57 -> 639.2 | J6: ='FORECAST SCHEDULES'!K57 -> 623.61 | K6: ='FORECAST SCHEDULES'!L57 -> 608.02 | L6: ='FORECAST SCHEDULES'!M57 -> 592.43
B7: Net PPE | C7: =SUM(C5:C6) -> 794.93 | D7: =SUM(D5:D6) -> 956.56 | E7: =SUM(E5:E6) -> 1006.97 | F7: =SUM(F5:F6) -> 819.65 | G7: =SUM(G5:G6) -> 1444.32 | H7: =SUM(H5:H6) -> 1410.2395 | I7: =SUM(I5:I6) -> 1377.507 | J7: =SUM(J5:J6) -> 1355.1978 | ... L7: =SUM(L5:L6) -> 1241.999
B9: Capital Work-in-Progress | C9: 80.15 | D9: 86.94 | E9: 61.62 | F9: 68.24 | G9: 133.2 | H9: ='FORECAST SCHEDULES'!I21 -> 147 | I9: ='FORECAST SCHEDULES'!J21 -> 177 | J9: ='FORECAST SCHEDULES'!K21 -> 217 | K9: ='FORECAST SCHEDULES'!L21 -> 242 | L9: ='FORECAST SCHEDULES'!M21 -> 257
B10: Other Intangible Assets | C10: 11.92 | D10: 8.06 | E10: 17.36 | F10: 18.29 | G10: 21.4 | H10: ='ASSUMPTIONS AND REASONING'!J32 -> 21.4 | I10: ='ASSUMPTIONS AND REASONING'!K32 -> 21.4 | J10: ='ASSUMPTIONS AND REASONING'!L32 -> 21.4 | K10: ='ASSUMPTIONS AND REASONING'!M32 -> 21.4 | L10: ='ASSUMPTIONS AND REASONING'!N32 -> 21.4
B11: Intangible Assets under Development | C11: 0 | D11: 0 | E11: 0 | F11: 3.39 | G11: 0 | H11: ='ASSUMPTIONS AND REASONING'!J33 -> 0 | I11: ='ASSUMPTIONS AND REASONING'!K33 -> 0 | J11: ='ASSUMPTIONS AND REASONING'!L33 -> 0 | K11: ='ASSUMPTIONS AND REASONING'!M33 -> 0 | L11: ='ASSUMPTIONS AND REASONING'!N33 -> 0
B12: Long-Term Investments | C12: 6 | D12: 6 | E12: 6 | F12: 6 | G12: 6 | H12: ='FORECAST SCHEDULES'!I150 -> 6 | I12: ='FORECAST SCHEDULES'!J150 -> 6 | J12: ='FORECAST SCHEDULES'!K150 -> 6 | K12: ='FORECAST SCHEDULES'!L150 -> 6 | L12: ='FORECAST SCHEDULES'!M150 -> 6
B13: Long-Term Trade Receivable | C13: 15.44 | D13: 17.73 | E13: 18.02 | F13: 17.65 | G13: 17.73 | H13: ='ASSUMPTIONS AND REASONING'!J34 -> 17.73 | I13: ='ASSUMPTIONS AND REASONING'!K34 -> 17.73 | J13: ='ASSUMPTIONS AND REASONING'!L34 -> 17.73 | K13: ='ASSUMPTIONS AND REASONING'!M34 -> 17.73 | L13: ='ASSUMPTIONS AND REASONING'!N34 -> 17.73
B14: Long-Term Loans | C14: 7.1 | D14: 0 | E14: 0 | F14: 20 | G14: 20 | H14: ='ASSUMPTIONS AND REASONING'!J35 -> 20 | I14: ='ASSUMPTIONS AND REASONING'!K35 -> 20 | J14: ='ASSUMPTIONS AND REASONING'!L35 -> 20 | K14: ='ASSUMPTIONS AND REASONING'!M35 -> 20 | L14: ='ASSUMPTIONS AND REASONING'!N35 -> 20
B15: Other Long-Term Financial Assets | C15: 141.59 | D15: 141.16 | E15: 131.67 | F15: 137.45 | G15: 145.98 | H15: ='ASSUMPTIONS AND REASONING'!J36 -> 154.0089 | I15: ='ASSUMPTIONS AND REASONING'!K36 -> 162.47939 | J15: ='ASSUMPTIONS AND REASONING'!L36 -> 171.41576 | K15: ='ASSUMPTIONS AND REASONING'!M36 -> 180.84362 | L15: ='ASSUMPTIONS AND REASONING'!N36 -> 190.79002
B16: Deferred Tax Assets (net) | C16: 423.61 | D16: 446.83 | E16: 450.1 | F16: 599.8 | G16: 678.27 | H16: ='FORECAST SCHEDULES'!I104 -> 776.24008 | I16: ='FORECAST SCHEDULES'!J104 -> 763.00123 | J16: ='FORECAST SCHEDULES'!K104 -> 753.91835 | K16: ='FORECAST SCHEDULES'!L104 -> 748.28508 | L16: ='FORECAST SCHEDULES'!M104 -> 749.93194
B17: Non-Current Tax Assets (net) | C17: 218.82 | D17: 313.2 | E17: 265.5 | F17: 178.56 | G17: 259.21 | H17: ='ASSUMPTIONS AND REASONING'!J47 -> 234.42333 | I17: ='ASSUMPTIONS AND REASONING'!K47 -> 224.06444 | J17: ='ASSUMPTIONS AND REASONING'!L47 -> 239.23259 | K17: ='ASSUMPTIONS AND REASONING'!M47 -> 232.57346 | L17: ='ASSUMPTIONS AND REASONING'!N47 -> 231.95683
B18: Capital Advances | C18: 1.04 | D18: 3.43 | E18: 8.69 | F18: 439.86 | G18: 115.36 | H18: ='FORECAST SCHEDULES'!I99 -> 350.36 | I18: ='FORECAST SCHEDULES'!J99 -> 400.36 | J18: ='FORECAST SCHEDULES'!K99 -> 350.36 | K18: ='FORECAST SCHEDULES'!L99 -> 200.36 | L18: ='FORECAST SCHEDULES'!M99 -> 50.36
B19: Other Non-Current Assets | C19: 841.02 | D19: 724.49 | E19: 829.45 | F19: 678.94 | G19: 393.4 | H19: ='ASSUMPTIONS AND REASONING'!J37 -> 633.93 | I19: ='ASSUMPTIONS AND REASONING'!K37 -> 568.75667 | J19: ='ASSUMPTIONS AND REASONING'!L37 -> 532.02889 | K19: ='ASSUMPTIONS AND REASONING'!M37 -> 578.23852 | L19: ='ASSUMPTIONS AND REASONING'!N37 -> 559.67469
B20: Total Non-Current Assets | C20: =SUM(C7:C19) -> 2541.62 | D20: =SUM(D7:D19) -> 2704.4 | E20: =SUM(E7:E19) -> 2795.38 | F20: =SUM(F7:F19) -> 2987.83 | G20: =SUM(G7:G19) -> 3234.87 | H20: =SUM(H7:H19) -> 3771.3318 | I20: =SUM(I7:I19) -> 3738.2987 | J20: =SUM(J7:J19) -> 3684.2834 | ... L20: =SUM(L7:L19) -> 3346.8425
B22: Current assets
B23: Raw Materials & Stores | C23: 130.82 | D23: 138.92 | E23: 103.4 | F23: 113.3 | G23: 432.21 | H23: ='FORECAST SCHEDULES'!I74 -> 215.36178 | I23: ='FORECAST SCHEDULES'!J74 -> 246.31663 | J23: ='FORECAST SCHEDULES'!K74 -> 275.52125 | K23: ='FORECAST SCHEDULES'!L74 -> 247.4617 | L23: ='FORECAST SCHEDULES'!M74 -> 301.72759
B24: Equipment for Specific Projects (WIP) | C24: 5755.96 | D24: 7557.16 | E24: 7241.44 | F24: 5590.7 | G24: 4096.52 | H24: ='FORECAST SCHEDULES'!I75 -> 4778.811 | I24: ='FORECAST SCHEDULES'!J75 -> 4418.3207 | J24: ='FORECAST SCHEDULES'!K75 -> 4043.8732 | K24: ='FORECAST SCHEDULES'!L75 -> 4400.749 | L24: ='FORECAST SCHEDULES'!M75 -> 5028.2083
B25: Scrap | C25: 1.83 | D25: 4.02 | E25: 12.02 | F25: 9.37 | G25: 8.35 | H25: ='FORECAST SCHEDULES'!I77 -> 8.5283595 | I25: ='FORECAST SCHEDULES'!J77 -> 8.0762473 | J25: ='FORECAST SCHEDULES'!K77 -> 7.6061842 | K25: ='FORECAST SCHEDULES'!L77 -> 8.0568607 | L25: ='FORECAST SCHEDULES'!M77 -> 9.2841079
B26: Inventories | C26: =SUM(C23:C25) -> 5888.61 | D26: =SUM(D23:D25) -> 7700.1 | E26: =SUM(E23:E25) -> 7356.86 | F26: =SUM(F23:F25) -> 5713.37 | G26: =SUM(G23:G25) -> 4537.08 | H26: ='FORECAST SCHEDULES'!I73 -> 5002.7012 | I26: ='FORECAST SCHEDULES'!J73 -> 4672.7136 | J26: ='FORECAST SCHEDULES'!K73 -> 4327.0007 | K26: ='FORECAST SCHEDULES'!L73 -> 4656.2676 | L26: ='FORECAST SCHEDULES'!M73 -> 5339.22
B28: Trade Receivables | C28: 965.94 | D28: 1005.41 | E28: 1002.33 | F28: 1846.93 | G28: 1067.21 | H28: ='FORECAST SCHEDULES'!I67 -> 1785.2824 | I28: ='FORECAST SCHEDULES'!J67 -> 1962.3402 | J28: ='FORECAST SCHEDULES'!K67 -> 1867.6878 | K28: ='FORECAST SCHEDULES'!L67 -> 2289.8861 | L28: ='FORECAST SCHEDULES'!M67 -> 2609.5963
B29: Cash and Cash Equivalents | C29: 739.91 | D29: 720.47 | E29: 1868.42 | F29: 5218.48 | G29: 5285.39 | H29: ='FORECAST SCHEDULES'!I169 -> 1275.6738 | I29: ='FORECAST SCHEDULES'!J169 -> 3392.0466 | J29: ='FORECAST SCHEDULES'!K169 -> 7220.1188 | K29: ='FORECAST SCHEDULES'!L169 -> 8678.0392 | L29: ='FORECAST SCHEDULES'!M169 -> 11203.679
B30: Bank Balances (Other than Cash) | C30: 7288 | D30: 10760 | E30: 11418 | F30: 8991.15 | G30: 10864.22 | H30: ='FORECAST SCHEDULES'!I170 -> 5430.963 | I30: ='FORECAST SCHEDULES'!J170 -> 11185.144 | J30: ='FORECAST SCHEDULES'!K170 -> 20192.652 | K30: ='FORECAST SCHEDULES'!L170 -> 29256.457 | L30: ='FORECAST SCHEDULES'!M170 -> 35166.318
B31: Current Loans | C31: 2.12 | D31: 0 | E31: 0 | F31: 0 | G31: 0 | H31: ='ASSUMPTIONS AND REASONING'!J38 -> 0 | I31: ='ASSUMPTIONS AND REASONING'!K38 -> 0 | J31: ='ASSUMPTIONS AND REASONING'!L38 -> 0 | K31: ='ASSUMPTIONS AND REASONING'!M38 -> 0 | L31: ='ASSUMPTIONS AND REASONING'!N38 -> 0
B32: Other Current Financial Assets | C32: 139.59 | D32: 140.66 | E32: 221.4 | F32: 307.56 | G32: 286.81 | H32: ='ASSUMPTIONS AND REASONING'!J39*'FORECAST SCHEDULES'!I223 -> 226.82934 | I32: ='ASSUMPTIONS AND REASONING'!K39*'FORECAST SCHEDULES'!J223 -> 230.19928 | J32: ='ASSUMPTIONS AND REASONING'!L39*'FORECAST SCHEDULES'!K223 -> 462.39876 | K32: ='ASSUMPTIONS AND REASONING'!M39*'FORECAST SCHEDULES'!L223 -> 678.64058 | L32: ='ASSUMPTIONS AND REASONING'!N39*'FORECAST SCHEDULES'!M223 -> 889.86437
B33: Contract Assets | C33: 213.7 | D33: 407 | E33: 283.23 | F33: 57.3 | G33: 604.84 | H33: ='ASSUMPTIONS AND REASONING'!J42 -> 677.4208 | I33: ='ASSUMPTIONS AND REASONING'!K42 -> 738.38867 | J33: ='ASSUMPTIONS AND REASONING'!L42 -> 812.22754 | K33: ='ASSUMPTIONS AND REASONING'!M42 -> 925.93939 | L33: ='ASSUMPTIONS AND REASONING'!N42 -> 1074.0897
B34: Assets Held for Sale | C34: 0.35 | D34: 0.44 | E34: 0.32 | F34: 0.07 | G34: 0.06 | H34: ='ASSUMPTIONS AND REASONING'!J40 -> 0 | I34: ='ASSUMPTIONS AND REASONING'!K40 -> 0 | J34: ='ASSUMPTIONS AND REASONING'!L40 -> 0 | K34: ='ASSUMPTIONS AND REASONING'!M40 -> 0 | L34: ='ASSUMPTIONS AND REASONING'!N40 -> 0
B35: Other Current Assets | C35: 6846.02 | D35: 5795.36 | E35: 3934.63 | F35: 3653.33 | G35: 2068.2 | H35: ='ASSUMPTIONS AND REASONING'!J41*SUM('INCOME STATEMENT'!H12:H13) -> 4465.3405 | I35: ='ASSUMPTIONS AND REASONING'!K41*SUM('INCOME STATEMENT'!I12:I13) -> 4162.2122 | J35: ='ASSUMPTIONS AND REASONING'!L41*SUM('INCOME STATEMENT'!J12:J13) -> 4132.6295 | K35: ='ASSUMPTIONS AND REASONING'!M41*SUM('INCOME STATEMENT'!K12:K13) -> 5267.3115 | L35: ='ASSUMPTIONS AND REASONING'!N41*SUM('INCOME STATEMENT'!L12:L13) -> 5813.6788
B36: Total Current Assets | C36: =SUM(C26:C35) -> 22084.24 | D36: =SUM(D26:D35) -> 26529.44 | E36: =SUM(E26:E35) -> 26085.19 | F36: =SUM(F26:F35) -> 25788.19 | G36: =SUM(G26:G35) -> 24713.81 | H36: =SUM(H26:H35) -> 18864.211 | I36: =SUM(I26:I35) -> 26343.045 | J36: =SUM(J26:J35) -> 39014.714 | ... L36: =SUM(L26:L35) -> 62096.446
B38: TOTAL ASSETS | C38: =C20+C36 -> 24625.86 | D38: =D20+D36 -> 29233.84 | E38: =E20+E36 -> 28880.57 | F38: =F20+F36 -> 28776.02 | G38: =G20+G36 -> 27948.68 | H38: =H20+H36 -> 22635.543 | I38: =I20+I36 -> 30081.343 | J38: =J20+J36 -> 42698.998 | ... L38: =L20+L36 -> 65443.288
B40: EQUITY AND LIABILITIES
B42: Equity
B43: Equity Share Capital | C43: 201.69 | D43: 201.69 | E43: 201.69 | F43: 201.69 | G43: 201.69 | H43: 201.69 | I43: 201.69 | J43: 201.69 | K43: 201.69 | L43: 201.69
B44: Other Equity | C44: 2717.37 | D44: 3119.67 | E44: 3975.87 | F44: 5368.99 | G44: 6979.15 | H44: =SUM('FORECAST SCHEDULES'!I183,'FORECAST SCHEDULES'!I188) -> 8575.2767 | I44: =SUM('FORECAST SCHEDULES'!J183,'FORECAST SCHEDULES'!J188) -> 10339.868 | J44: =SUM('FORECAST SCHEDULES'!K183,'FORECAST SCHEDULES'!K188) -> 12649.424 | K44: =SUM('FORECAST SCHEDULES'!L183,'FORECAST SCHEDULES'!L188) -> 15499.61 | L44: =SUM('FORECAST SCHEDULES'!M183,'FORECAST SCHEDULES'!M188) -> 18994.865
B45: Total Equity | C45: =C43+C44 -> 2919.06 | D45: =D43+D44 -> 3321.36 | E45: =E43+E44 -> 4177.56 | F45: =F43+F44 -> 5570.68 | G45: =G43+G44 -> 7180.84 | H45: =H43+H44 -> 8776.9667 | I45: =I43+I44 -> 10541.558 | J45: =J43+J44 -> 12851.114 | ... L45: =L43+L44 -> 19196.555
B47: Non-current liabilities
...

Sheet CASH FLOW STATEMENT 
C1: ACTUAL | D1: ACTUAL | E1: ACTUAL | F1: ACTUAL | G1: ACTUAL | H1: FOCASTED | I1: FOCASTED | J1: FOCASTED | K1: FOCASTED | L1: FOCASTED
B2: Period Ending | C2: 44286 | D2: 44651 | E2: 45016 | F2: 45382 | G2: 45747 | H2: 46112 | I2: 46477 | J2: 46843 | K2: 47208 | L2: 47573
B3: A. Cash flow from operating activities
B4: Profit before tax | D4: ='INCOME STATEMENT'!D53 -> 772.69 | E4: ='INCOME STATEMENT'!E53 -> 1429.33 | F4: ='INCOME STATEMENT'!F53 -> 2461.38 | G4: ='INCOME STATEMENT'!G53 -> 3109.2 | H4: ='INCOME STATEMENT'!H53 -> 2690.4874 | I4: ='INCOME STATEMENT'!I53 -> 3284.3806 | J4: ='INCOME STATEMENT'!J53 -> 4277.5728 | K4: ='INCOME STATEMENT'!K53 -> 5252.5944 | L4: ='INCOME STATEMENT'!L53 -> 6480.7133
B6: Non-cash & non-operating expenses
B7: Depreciation & amortization | D7: ='INCOME STATEMENT'!D34 -> 74.51 | E7: ='INCOME STATEMENT'!E34 -> 75.58 | F7: ='INCOME STATEMENT'!F34 -> 83.13 | G7: ='INCOME STATEMENT'!G34 -> 115.19 | H7: ='INCOME STATEMENT'!H34 -> 100.79368 | I7: ='INCOME STATEMENT'!I34 -> 105.47308 | J7: ='INCOME STATEMENT'!J34 -> 110.25537 | K7: ='INCOME STATEMENT'!K34 -> 108.39913 | L7: ='INCOME STATEMENT'!L34 -> 110.27304
B8: Finance cost | D8: =-'INCOME STATEMENT'!D42 -> 7.16 | E8: =-'INCOME STATEMENT'!E42 -> 6.37 | F8: =-'INCOME STATEMENT'!F42 -> 5.12 | G8: =-'INCOME STATEMENT'!G42 -> 4.4 | H8: =-'INCOME STATEMENT'!H42 -> 5.5123559 | I8: =-'INCOME STATEMENT'!I42 -> 5.4041863 | J8: =-'INCOME STATEMENT'!J42 -> 5.4154387 | K8: =-'INCOME STATEMENT'!K42 -> 5.443969 | L8: =-'INCOME STATEMENT'!L42 -> 5.4212005
B9: Amortization of prepaid rentals | D9: 0.15 | E9: 0.15 | F9: 0.15 | G9: 0 | H9: ='ASSUMPTIONS AND REASONING'!J50 -> 0 | I9: ='ASSUMPTIONS AND REASONING'!K50 -> 0 | J9: ='ASSUMPTIONS AND REASONING'!L50 -> 0 | K9: ='ASSUMPTIONS AND REASONING'!M50 -> 0 | L9: ='ASSUMPTIONS AND REASONING'!N50 -> 0
B10: FX variation | D10: 0 | E10: 0 | F10: 0.02 | G10: 1.27 | H10: ='ASSUMPTIONS AND REASONING'!J51 -> 0 | I10: ='ASSUMPTIONS AND REASONING'!K51 -> 0 | J10: ='ASSUMPTIONS AND REASONING'!L51 -> 0 | K10: ='ASSUMPTIONS AND REASONING'!M51 -> 0 | L10: ='ASSUMPTIONS AND REASONING'!N51 -> 0
B12: Non-operating income (reversals)
B13: Gain on sale of fixed assets | D13: 2.56 | E13: -0.9 | F13: -1.48 | G13: -0.79 | H13: =-'INCOME STATEMENT'!H50 -> 0 | I13: =-'INCOME STATEMENT'!I50 -> 0 | J13: =-'INCOME STATEMENT'!J50 -> 0 | K13: =-'INCOME STATEMENT'!K50 -> 0 | L13: =-'INCOME STATEMENT'!L50 -> 0
B14: Dividend received | D14: =-'INCOME STATEMENT'!D45 -> -23.36 | E14: =-'INCOME STATEMENT'!E45 -> -26.65 | F14: =-'INCOME STATEMENT'!F45 -> -36.55 | G14: =-'INCOME STATEMENT'!G45 -> -47.54 | H14: =-'INCOME STATEMENT'!H45 -> -50 | I14: =-'INCOME STATEMENT'!I45 -> -50 | J14: =-'INCOME STATEMENT'!J45 -> -50 | K14: =-'INCOME STATEMENT'!K45 -> -50 | L14: =-'INCOME STATEMENT'!L45 -> -50
B15: Amortization of deferred vendor deposits | D15: -0.07 | E15: -0.05 | F15: -0.04 | G15: -0.06 | H15: ='ASSUMPTIONS AND REASONING'!J52 -> -0.06 | I15: ='ASSUMPTIONS AND REASONING'!K52 -> -0.06 | J15: ='ASSUMPTIONS AND REASONING'!L52 -> -0.06 | K15: ='ASSUMPTIONS AND REASONING'!M52 -> -0.06 | L15: ='ASSUMPTIONS AND REASONING'!N52 -> -0.06
B16: Amortization of deferred revenue | D16: -7.63 | E16: -6.87 | F16: -6.87 | G16: -6.87 | H16: ='ASSUMPTIONS AND REASONING'!J53 -> -6.87 | I16: ='ASSUMPTIONS AND REASONING'!K53 -> -6.87 | J16: ='ASSUMPTIONS AND REASONING'!L53 -> -6.87 | K16: ='ASSUMPTIONS AND REASONING'!M53 -> -6.87 | L16: ='ASSUMPTIONS AND REASONING'!N53 -> -6.87
B17: Interest on deferred payment liability | D17: -3.98 | E17: -4.74 | F17: -4.33 | G17: -4.27 | H17: =-'INCOME STATEMENT'!H39 -> -4.4597137 | I17: =-'INCOME STATEMENT'!I39 -> -4.353149 | J17: =-'INCOME STATEMENT'!J39 -> -4.3608543 | K17: =-'INCOME STATEMENT'!K39 -> -4.3912087 | L17: =-'INCOME STATEMENT'!L39 -> -4.3684011
B18: Interest on deferred deposit with MbPT | D18: -0.22 | E18: -0.23 | F18: -0.25 | G18: 0 | H18: ='ASSUMPTIONS AND REASONING'!J54 -> 0 | I18: ='ASSUMPTIONS AND REASONING'!K54 -> 0 | J18: ='ASSUMPTIONS AND REASONING'!L54 -> 0 | K18: ='ASSUMPTIONS AND REASONING'!M54 -> 0 | L18: ='ASSUMPTIONS AND REASONING'!N54 -> 0
B19: Operating profit before working capital changes | D19: =D4+SUM(D7:D18) -> 821.81 | E19: =E4+SUM(E7:E18) -> 1471.99 | F19: =F4+SUM(F7:F18) -> 2500.28 | G19: =G4+SUM(G7:G18) -> 3170.53 | H19: =H4+SUM(H7:H18) -> 2735.4037 | I19: =I4+SUM(I7:I18) -> 3333.9748 | J19: =J4+SUM(J7:J18) -> 4331.9527 | K19: =K4+SUM(K7:K18) -> 5305.1163 | L19: =L4+SUM(L7:L18) -> 6535.1091
B21: Working capital movements
B22: Change in inventories | D22: ='BALANCE SHEET'!C26-'BALANCE SHEET'!D26 -> -1811.49 | E22: ='BALANCE SHEET'!D26-'BALANCE SHEET'!E26 -> 343.24 | F22: ='BALANCE SHEET'!E26-'BALANCE SHEET'!F26 -> 1643.49 | G22: ='BALANCE SHEET'!F26-'BALANCE SHEET'!G26 -> 1176.29 | H22: ='BALANCE SHEET'!G26-'BALANCE SHEET'!H26 -> -465.62118 | I22: ='BALANCE SHEET'!H26-'BALANCE SHEET'!I26 -> 329.98756 | J22: ='BALANCE SHEET'!I26-'BALANCE SHEET'!J26 -> 345.71295 | K22: ='BALANCE SHEET'!J26-'BALANCE SHEET'!K26 -> -329.26689 | L22: ='BALANCE SHEET'!K26-'BALANCE SHEET'!L26 -> -682.95241
B23: Change in trade receivables & loans | D23: =('BALANCE SHEET'!C13+'BALANCE SHEET'!C28+'BALANCE SHEET'!C14+'BALANCE SHEET'!C31)-('BALANCE SHEET'!D13+'BALANCE SHEET'!D28+'BALANCE SHEET'!D14+'BALANCE SHEET'!D31) -> -32.54 | E23: =('BALANCE SHEET'!D13+'BALANCE SHEET'!D28+'BALANCE SHEET'!D14+'BALANCE SHEET'!D31)-('BALANCE SHEET'!E13+'BALANCE SHEET'!E28+'BALANCE SHEET'!E14+'BALANCE SHEET'!E31) -> 2.79 | F23: =('BALANCE SHEET'!E13+'BALANCE SHEET'!E28+'BALANCE SHEET'!E14+'BALANCE SHEET'!E31)-('BALANCE SHEET'!F13+'BALANCE SHEET'!F28+'BALANCE SHEET'!F14+'BALANCE SHEET'!F31) -> -864.23 | G23: =('BALANCE SHEET'!F13+'BALANCE SHEET'!F28+'BALANCE SHEET'!F14+'BALANCE SHEET'!F31)-('BALANCE SHEET'!G13+'BALANCE SHEET'!G28+'BALANCE SHEET'!G14+'BALANCE SHEET'!G31) -> 779.64 | H23: =('BALANCE SHEET'!G13+'BALANCE SHEET'!G28+'BALANCE SHEET'!G14+'BALANCE SHEET'!G31)-('BALANCE SHEET'!H13+'BALANCE SHEET'!H28+'BALANCE SHEET'!H14+'BALANCE SHEET'!H31) -> -718.07236 | I23: =('BALANCE SHEET'!H13+'BALANCE SHEET'!H28+'BALANCE SHEET'!H14+'BALANCE SHEET'!H31)-('BALANCE SHEET'!I13+'BALANCE SHEET'!I28+'BALANCE SHEET'!I14+'BALANCE SHEET'!I31) -> -177.05788 | J23: =('BALANCE SHEET'!I13+'BALANCE SHEET'!I28+'BALANCE SHEET'!I14+'BALANCE SHEET'!I31)-('BALANCE SHEET'!J13+'BALANCE SHEET'!J28+'BALANCE SHEET'!J14+'BALANCE SHEET'!J31) -> 94.652456 | K23: =('BALANCE SHEET'!J13+'BALANCE SHEET'!J28+'BALANCE SHEET'!J14+'BALANCE SHEET'!J31)-('BALANCE SHEET'!K13+'BALANCE SHEET'!K28+'BALANCE SHEET'!K14+'BALANCE SHEET'!K31) -> -422.19835 | L23: =('BALANCE SHEET'!K13+'BALANCE SHEET'!K28+'BALANCE SHEET'!K14+'BALANCE SHEET'!K31)-('BALANCE SHEET'!L13+'BALANCE SHEET'!L28+'BALANCE SHEET'!L14+'BALANCE SHEET'!L31) -> -319.71018
B24: Change in other current & non-current assets | D24: =('BALANCE SHEET'!C15+'BALANCE SHEET'!C17+'BALANCE SHEET'!C19+'BALANCE SHEET'!C33+'BALANCE SHEET'!C34+'BALANCE SHEET'!C35)-('BALANCE SHEET'!D15+'BALANCE SHEET'!D17+'BALANCE SHEET'!D19+'BALANCE SHEET'!D33+'BALANCE SHEET'!D34+'BALANCE SHEET'!D35) -> 879.85 | E24: =('BALANCE SHEET'!D15+'BALANCE SHEET'!D17+'BALANCE SHEET'!D19+'BALANCE SHEET'!D33+'BALANCE SHEET'!D34+'BALANCE SHEET'!D35)-('BALANCE SHEET'!E15+'BALANCE SHEET'!E17+'BALANCE SHEET'!E19+'BALANCE SHEET'!E33+'BALANCE SHEET'!E34+'BALANCE SHEET'!E35) -> 1936.85 | F24: =('BALANCE SHEET'!E15+'BALANCE SHEET'!E17+'BALANCE SHEET'!E19+'BALANCE SHEET'!E33+'BALANCE SHEET'!E34+'BALANCE SHEET'!E35)-('BALANCE SHEET'!F15+'BALANCE SHEET'!F17+'BALANCE SHEET'!F19+'BALANCE SHEET'!F33+'BALANCE SHEET'!F34+'BALANCE SHEET'!F35) -> 739.15 | G24: =('BALANCE SHEET'!F15+'BALANCE SHEET'!F17+'BALANCE SHEET'!F19+'BALANCE SHEET'!F33+'BALANCE SHEET'!F34+'BALANCE SHEET'!F35)-('BALANCE SHEET'!G15+'BALANCE SHEET'!G17+'BALANCE SHEET'!G19+'BALANCE SHEET'!G33+'BALANCE SHEET'!G34+'BALANCE SHEET'!G35) -> 1233.96 | H24: =('BALANCE SHEET'!G15+'BALANCE SHEET'!G17+'BALANCE SHEET'!G19+'BALANCE SHEET'!G33+'BALANCE SHEET'!G34+'BALANCE SHEET'!G35)-('BALANCE SHEET'!H15+'BALANCE SHEET'!H17+'BALANCE SHEET'!H19+'BALANCE SHEET'!H33+'BALANCE SHEET'!H34+'BALANCE SHEET'!H35) -> -2693.4335 | I24: =('BALANCE SHEET'!H15+'BALANCE SHEET'!H17+'BALANCE SHEET'!H19+'BALANCE SHEET'!H33+'BALANCE SHEET'!H34+'BALANCE SHEET'!H35)-('BALANCE SHEET'!I15+'BALANCE SHEET'!I17+'BALANCE SHEET'!I19+'BALANCE SHEET'!I33+'BALANCE SHEET'!I34+'BALANCE SHEET'!I35) -> 309.22214 | J24: =('BALANCE SHEET'!I15+'BALANCE SHEET'!I17+'BALANCE SHEET'!I19+'BALANCE SHEET'!I33+'BALANCE SHEET'!I34+'BALANCE SHEET'!I35)-('BALANCE SHEET'!J15+'BALANCE SHEET'!J17+'BALANCE SHEET'!J19+'BALANCE SHEET'!J33+'BALANCE SHEET'!J34+'BALANCE SHEET'!J35) -> -31.63286 | K24: =('BALANCE SHEET'!J15+'BALANCE SHEET'!J17+'BALANCE SHEET'!J19+'BALANCE SHEET'!J33+'BALANCE SHEET'!J34+'BALANCE SHEET'!J35)-('BALANCE SHEET'!K15+'BALANCE SHEET'!K17+'BALANCE SHEET'!K19+'BALANCE SHEET'!K33+'BALANCE SHEET'!K34+'BALANCE SHEET'!K35) -> -1297.3723 | L24: =('BALANCE SHEET'!K15+'BALANCE SHEET'!K17+'BALANCE SHEET'!K19+'BALANCE SHEET'!K33+'BALANCE SHEET'!K34+'BALANCE SHEET'!K35)-('BALANCE SHEET'!L15+'BALANCE SHEET'!L17+'BALANCE SHEET'!L19+'BALANCE SHEET'!L33+'BALANCE SHEET'!L34+'BALANCE SHEET'!L35) -> -685.28351
B25: Change in trade payables & provisions | D25: =('BALANCE SHEET'!D49+'BALANCE SHEET'!D50+'BALANCE SHEET'!D62+'BALANCE SHEET'!D63+'BALANCE SHEET'!D55+'BALANCE SHEET'!D70)-('BALANCE SHEET'!C49+'BALANCE SHEET'!C50+'BALANCE SHEET'!C62+'BALANCE SHEET'!C63+'BALANCE SHEET'!C55+'BALANCE SHEET'!C70) -> -314.91 | E25: =('BALANCE SHEET'!E49+'BALANCE SHEET'!E50+'BALANCE SHEET'!E62+'BALANCE SHEET'!E63+'BALANCE SHEET'!E55+'BALANCE SHEET'!E70)-('BALANCE SHEET'!D49+'BALANCE SHEET'!D50+'BALANCE SHEET'!D62+'BALANCE SHEET'!D63+'BALANCE SHEET'!D55+'BALANCE SHEET'!D70) -> -1796.99 | F25: =('BALANCE SHEET'!F49+'BALANCE SHEET'!F50+'BALANCE SHEET'!F62+'BALANCE SHEET'!F63+'BALANCE SHEET'!F55+'BALANCE SHEET'!F70)-('BALANCE SHEET'!E49+'BALANCE SHEET'!E50+'BALANCE SHEET'!E62+'BALANCE SHEET'!E63+'BALANCE SHEET'!E55+'BALANCE SHEET'!E70) -> -1.7 | G25: =('BALANCE SHEET'!G49+'BALANCE SHEET'!G50+'BALANCE SHEET'!G62+'BALANCE SHEET'!G63+'BALANCE SHEET'!G55+'BALANCE SHEET'!G70)-('BALANCE SHEET'!F49+'BALANCE SHEET'!F50+'BALANCE SHEET'!F62+'BALANCE SHEET'!F63+'BALANCE SHEET'!F55+'BALANCE SHEET'!F70) -> -221.02 | H25: =('BALANCE SHEET'!H49+'BALANCE SHEET'!H50+'BALANCE SHEET'!H62+'BALANCE SHEET'!H63+'BALANCE SHEET'!H55+'BALANCE SHEET'!H70)-('BALANCE SHEET'!G49+'BALANCE SHEET'!G50+'BALANCE SHEET'!G62+'BALANCE SHEET'!G63+'BALANCE SHEET'!G55+'BALANCE SHEET'!G70) -> 472.7613 | I25: =('BALANCE SHEET'!I49+'BALANCE SHEET'!I50+'BALANCE SHEET'!I62+'BALANCE SHEET'!I63+'BALANCE SHEET'!I55+'BALANCE SHEET'!I70)-('BALANCE SHEET'!H49+'BALANCE SHEET'!H50+'BALANCE SHEET'!H62+'BALANCE SHEET'!H63+'BALANCE SHEET'!H55+'BALANCE SHEET'!H70) -> -414.3019 | J25: =('BALANCE SHEET'!J49+'BALANCE SHEET'!J50+'BALANCE SHEET'!J62+'BALANCE SHEET'!J63+'BALANCE SHEET'!J55+'BALANCE SHEET'!J70)-('BALANCE SHEET'!I49+'BALANCE SHEET'!I50+'BALANCE SHEET'!I62+'BALANCE SHEET'!I63+'BALANCE SHEET'!I55+'BALANCE SHEET'!I70) -> 272.1825 | K25: =('BALANCE SHEET'!K49+'BALANCE SHEET'!K50+'BALANCE SHEET'!K62+'BALANCE SHEET'!K63+'BALANCE SHEET'!K55+'BALANCE SHEET'!K70)-('BALANCE SHEET'!J49+'BALANCE SHEET'!J50+'BALANCE SHEET'!J62+'BALANCE SHEET'!J63+'BALANCE SHEET'!J55+'BALANCE SHEET'!J70) -> 653.73797 | L25: =('BALANCE SHEET'!L49+'BALANCE SHEET'!L50+'BALANCE SHEET'!L62+'BALANCE SHEET'!L63+'BALANCE SHEET'!L55+'BALANCE SHEET'!L70)-('BALANCE SHEET'!K49+'BALANCE SHEET'!K50+'BALANCE SHEET'!K62+'BALANCE SHEET'!K63+'BALANCE SHEET'!K55+'BALANCE SHEET'!K70) -> 742.50065
B26: Change in other current & non-current liabilities | D26: =('BALANCE SHEET'!D51+'BALANCE SHEET'!D57+'BALANCE SHEET'!D64+'BALANCE SHEET'!D65+'BALANCE SHEET'!D66)-('BALANCE SHEET'!C51+'BALANCE SHEET'!C57+'BALANCE SHEET'!C64+'BALANCE SHEET'!C65+'BALANCE SHEET'!C66) -> 4508.95 | E26: =('BALANCE SHEET'!E51+'BALANCE SHEET'!E57+'BALANCE SHEET'!E64+'BALANCE SHEET'!E65+'BALANCE SHEET'!E66)-('BALANCE SHEET'!D51+'BALANCE SHEET'!D57+'BALANCE SHEET'!D64+'BALANCE SHEET'!D65+'BALANCE SHEET'!D66) -> 593.12 | F26: =('BALANCE SHEET'!F51+'BALANCE SHEET'!F57+'BALANCE SHEET'!F64+'BALANCE SHEET'!F65+'BALANCE SHEET'!F66)-('BALANCE SHEET'!E51+'BALANCE SHEET'!E57+'BALANCE SHEET'!E64+'BALANCE SHEET'!E65+'BALANCE SHEET'!E66) -> -1506.48 | G26: =('BALANCE SHEET'!G51+'BALANCE SHEET'!G57+'BALANCE SHEET'!G64+'BALANCE SHEET'!G65+'BALANCE SHEET'!G66)-('BALANCE SHEET'!F51+'BALANCE SHEET'!F57+'BALANCE SHEET'!F64+'BALANCE SHEET'!F65+'BALANCE SHEET'!F66) -> -2220.26 | H26: =('BALANCE SHEET'!H51+'BALANCE SHEET'!H57+'BALANCE SHEET'!H64+'BALANCE SHEET'!H65+'BALANCE SHEET'!H66)-('BALANCE SHEET'!G51+'BALANCE SHEET'!G57+'BALANCE SHEET'!G64+'BALANCE SHEET'!G65+'BALANCE SHEET'!G66) -> -7379.5554 | I26: =('BALANCE SHEET'!I51+'BALANCE SHEET'!I57+'BALANCE SHEET'!I64+'BALANCE SHEET'!I65+'BALANCE SHEET'!I66)-('BALANCE SHEET'!H51+'BALANCE SHEET'!H57+'BALANCE SHEET'!H64+'BALANCE SHEET'!H65+'BALANCE SHEET'!H66) -> 6203.186 | J26: =('BALANCE SHEET'!J51+'BALANCE SHEET'!J57+'BALANCE SHEET'!J64+'BALANCE SHEET'!J65+'BALANCE SHEET'!J66)-('BALANCE SHEET'!I51+'BALANCE SHEET'!I57+'BALANCE SHEET'!I64+'BALANCE SHEET'!I65+'BALANCE SHEET'!I66) -> 9948.5708 | K26: =('BALANCE SHEET'!K51+'BALANCE SHEET'!K57+'BALANCE SHEET'!K64+'BALANCE SHEET'!K65+'BALANCE SHEET'!K66)-('BALANCE SHEET'!J51+'BALANCE SHEET'!J57+'BALANCE SHEET'!J64+'BALANCE SHEET'!J65+'BALANCE SHEET'!J66) -> 9019.9693 | L26: =('BALANCE SHEET'!L51+'BALANCE SHEET'!L57+'BALANCE SHEET'!L64+'BALANCE SHEET'!L65+'BALANCE SHEET'!L66)-('BALANCE SHEET'!K51+'BALANCE SHEET'!K57+'BALANCE SHEET'!K64+'BALANCE SHEET'!K65+'BALANCE SHEET'!K66) -> 5881.9455
B27: Cash flow from operations | D27: =D19+SUM(D22:D26) -> 4051.67 | E27: =E19+SUM(E22:E26) -> 2551 | F27: =F19+SUM(F22:F26) -> 2510.51 | G27: =G19+SUM(G22:G26) -> 3919.14 | H27: =H19+SUM(H22:H26) -> -8048.5175 | I27: =I19+SUM(I22:I26) -> 9585.0107 | J27: =J19+SUM(J22:J26) -> 14961.439 | K27: =K19+SUM(K22:K26) -> 12929.986 | L27: =L19+SUM(L22:L26) -> 11471.609
B29: Income tax paid (net of refunds) | D29: -302.45 | E29: -312.15 | F29: -677.16 | G29: -942.51 | H29: ='FORECAST SCHEDULES'!I216 -> -714.44893 | I29: ='FORECAST SCHEDULES'!J216 -> -923.78252 | J29: ='FORECAST SCHEDULES'!K216 -> -1211.9041 | K29: ='FORECAST SCHEDULES'!L216 -> -1453.441 | L29: ='FORECAST SCHEDULES'!M216 -> -1817.3872
B30: Net cash from operating activities | D30: =D27+D29 -> 3749.22 | E30: =E27+E29 -> 2238.85 | F30: =F27+F29 -> 1833.35 | G30: =G27+G29 -> 2976.63 | H30: =H27+H29 -> -8762.9664 | I30: =I27+I29 -> 8661.2282 | J30: =J27+J29 -> 13749.534 | K30: =K27+K29 -> 11476.545 | L30: =L27+L29 -> 9654.222
B31: Net cash from operating activities for intrest income | D31: =SUM('INCOME STATEMENT'!D36,'INCOME STATEMENT'!D38:D42,'INCOME STATEMENT'!D45:D47,D7:D10,D13:D18,D22:D26,D29) -> 3421.86 | E31: =SUM('INCOME STATEMENT'!E36,'INCOME STATEMENT'!E38:E42,'INCOME STATEMENT'!E45:E47,E7:E10,E13:E18,E22:E26,E29) -> 1642.55 | F31: =SUM('INCOME STATEMENT'!F36,'INCOME STATEMENT'!F38:F42,'INCOME STATEMENT'!F45:F47,F7:F10,F13:F18,F22:F26,F29) -> 842.58 | G31: =SUM('INCOME STATEMENT'!G36,'INCOME STATEMENT'!G38:G42,'INCOME STATEMENT'!G45:G47,G7:G10,G13:G18,G22:G26,G29) -> 1974.4 | H31: =SUM('INCOME STATEMENT'!H36,'INCOME STATEMENT'!H38:H42,'INCOME STATEMENT'!H45:H47,H7:H10,H13:H18,H22:H26) -> -8837.5755 | I31: =SUM('INCOME STATEMENT'!I36,'INCOME STATEMENT'!I38:I42,'INCOME STATEMENT'!I45:I47,I7:I10,I13:I18,I22:I26) -> 8831.9025 | J31: =SUM('INCOME STATEMENT'!J36,'INCOME STATEMENT'!J38:J42,'INCOME STATEMENT'!J45:J47,J7:J10,J13:J18,J22:J26) -> 13506.531 | K31: =SUM('INCOME STATEMENT'!K36,'INCOME STATEMENT'!K38:K42,'INCOME STATEMENT'!K45:K47,K7:K10,K13:K18,K22:K26) -> 10687.292 | L31: =SUM('INCOME STATEMENT'!L36,'INCOME STATEMENT'!L38:L42,'INCOME STATEMENT'!L45:L47,L7:L10,L13:L18,L22:L26) -> 8581.5841
B33: B. Cash flow from investing activities
B34: Purchase of PP&E | D34: -32.01 | E34: -135.57 | F34: 103.03 | G34: -743.14 | H34: =-('FORECAST SCHEDULES'!I11+'FORECAST SCHEDULES'!I54) -> -62 | I34: =-('FORECAST SCHEDULES'!J11+'FORECAST SCHEDULES'!J54) -> -67 | J34: =-('FORECAST SCHEDULES'!K11+'FORECAST SCHEDULES'!K54) -> -82 | K34: =-('FORECAST SCHEDULES'!L11+'FORECAST SCHEDULES'!L54) -> -47 | L34: =-('FORECAST SCHEDULES'!M11+'FORECAST SCHEDULES'!M54) -> -47
B35: Capital work in progress | D35: ='BALANCE SHEET'!C9-'BALANCE SHEET'!D9 -> -6.79 | E35: ='BALANCE SHEET'!D9-'BALANCE SHEET'!E9 -> 25.32 | F35: ='BALANCE SHEET'!E9-'BALANCE SHEET'!F9 -> -6.62 | G35: ='BALANCE SHEET'!F9-'BALANCE SHEET'!G9 -> -64.96 | H35: ='BALANCE SHEET'!G9-'BALANCE SHEET'!H9 -> -13.8 | I35: ='BALANCE SHEET'!H9-'BALANCE SHEET'!I9 -> -30 | J35: ='BALANCE SHEET'!I9-'BALANCE SHEET'!J9 -> -40 | K35: ='BALANCE SHEET'!J9-'BALANCE SHEET'!K9 -> -25 | L35: ='BALANCE SHEET'!K9-'BALANCE SHEET'!L9 -> -15
B36: Proceeds from sale of PP&E | D36: 1.27 | E36: 1.31 | F36: 1.66 | G36: 0.92 | H36: ='ASSUMPTIONS AND REASONING'!J55 -> 1.2966667 | I36: ='ASSUMPTIONS AND REASONING'!K55 -> 1.2922222 | J36: ='ASSUMPTIONS AND REASONING'!L55 -> 1.1696296 | K36: ='ASSUMPTIONS AND REASONING'!M55 -> 1.2528395 | L36: ='ASSUMPTIONS AND REASONING'!N55 -> 1.2382305
B37: Capital advance | D37: ='BALANCE SHEET'!C18-'BALANCE SHEET'!D18 -> -2.39 | E37: ='BALANCE SHEET'!D18-'BALANCE SHEET'!E18 -> -5.26 | F37: ='BALANCE SHEET'!E18-'BALANCE SHEET'!F18 -> -431.17 | G37: ='BALANCE SHEET'!F18-'BALANCE SHEET'!G18 -> 324.5 | H37: ='BALANCE SHEET'!G18-'BALANCE SHEET'!H18 -> -235 | I37: ='BALANCE SHEET'!H18-'BALANCE SHEET'!I18 -> -50 | J37: ='BALANCE SHEET'!I18-'BALANCE SHEET'!J18 -> 50 | K37: ='BALANCE SHEET'!J18-'BALANCE SHEET'!K18 -> 150 | L37: ='BALANCE SHEET'!K18-'BALANCE SHEET'!L18 -> 150
B38: Interest received | D38: ='INCOME STATEMENT'!D44 -> 347.48 | E38: ='INCOME STATEMENT'!E44 -> 601.77 | F38: ='INCOME STATEMENT'!F44 -> 994.41 | G38: ='INCOME STATEMENT'!G44 -> 1005.84 | H38: 0 | I38: 0 | J38: 0 | K38: 0 | L38: 0
B39: Dividend received | D39: ='INCOME STATEMENT'!D45 -> 23.36 | E39: ='INCOME STATEMENT'!E45 -> 26.65 | F39: ='INCOME STATEMENT'!F45 -> 36.55 | G39: ='INCOME STATEMENT'!G45 -> 47.54 | H39: ='INCOME STATEMENT'!H45 -> 50 | I39: ='INCOME STATEMENT'!I45 -> 50 | J39: ='INCOME STATEMENT'!J45 -> 50 | K39: ='INCOME STATEMENT'!K45 -> 50 | L39: ='INCOME STATEMENT'!L45 -> 50
B40: Fixed deposits / Term deposits | D40: =-('BALANCE SHEET'!D30-'BALANCE SHEET'!C30) -> -3472 | E40: =-('BALANCE SHEET'!E30-'BALANCE SHEET'!D30) -> -658 | F40: =-('BALANCE SHEET'!F30-'BALANCE SHEET'!E30) -> 2426.85 | G40: =-('BALANCE SHEET'!G30-'BALANCE SHEET'!F30) -> -1873.07 | H40: =-('BALANCE SHEET'!H30-'BALANCE SHEET'!G30) -> 5433.257 | I40: =-('BALANCE SHEET'!I30-'BALANCE SHEET'!H30) -> -5754.181 | J40: =-('BALANCE SHEET'!J30-'BALANCE SHEET'!I30) -> -9007.5075 | K40: =-('BALANCE SHEET'!K30-'BALANCE SHEET'!J30) -> -9063.8054 | L40: =-('BALANCE SHEET'!L30-'BALANCE SHEET'!K30) -> -5909.8606
B41: Lease principal payments | D41: -4.52 | E41: -5.88 | F41: -6.51 | G41: -0.12 | H41: ='FORECAST SCHEDULES'!I45 -> -2 | I41: ='FORECAST SCHEDULES'!J45 -> -2 | J41: ='FORECAST SCHEDULES'!K45 -> -2 | K41: ='FORECAST SCHEDULES'!L45 -> -2 | L41: ='FORECAST SCHEDULES'!M45 -> -2
B42: Net cash from investing activities | D42: =SUM(D34:D41) -> -3145.6 | E42: =SUM(E34:E41) -> -149.66 | F42: =SUM(F34:F41) -> 3118.2 | G42: =SUM(G34:G41) -> -1302.49 | H42: =SUM(H34:H41) -> 5171.7537 | I42: =SUM(I34:I41) -> -5851.8888 | J42: =SUM(J34:J41) -> -9030.3379 | K42: =SUM(K34:K41) -> -8936.5526 | L42: =SUM(L34:L41) -> -5772.6224
B44: C. Cash flow from financing activities
B45: Dividend paid | D45: -180.11 | E45: -216.42 | F45: -447.75 | G45: -711.97 | H45: =-'FORECAST SCHEDULES'!H203-'FORECAST SCHEDULES'!I201 -> -417.50353 | I45: =-'FORECAST SCHEDULES'!I203-'FORECAST SCHEDULES'!J201 -> -691.96658 | J45: =-'FORECAST SCHEDULES'!J203-'FORECAST SCHEDULES'!K201 -> -890.12433 | K45: =-'FORECAST SCHEDULES'!K203-'FORECAST SCHEDULES'!L201 -> -1081.072 | L45: =-'FORECAST SCHEDULES'!L203-'FORECAST SCHEDULES'!M201 -> -1354.9595
B46: Lease finance costs | D46: -3.1 | E46: -1.55 | F46: -0.75 | G46: -0.07 | H46: =-'INCOME STATEMENT'!H38 -> -1 | I46: =-'INCOME STATEMENT'!I38 -> -1 | J46: =-'INCOME STATEMENT'!J38 -> -1 | K46: =-'INCOME STATEMENT'!K38 -> -1 | L46: =-'INCOME STATEMENT'!L38 -> -1
...

Sheet FORECAST SCHEDULES
D1: ACTUAL | E1: ACTUAL | F1: ACTUAL | G1: ACTUAL | H1: ACTUAL | I1: FORECASTED | J1: FORECASTED | K1: FORECASTED | L1: FORECASTED | M1: FORECASTED
B2: LINE ITEM | C2: Methodology | D2: 44286 | E2: 44651 | F2: 45016 | G2: 45382 | H2: 45747 | I2: 46112 | J2: 46477 | K2: 46843 | L2: 47208 | M2: 47573 | O2: REASONING
B4: S01 — PP&E / Capital Expenditure / Depreciation & Amortization Roll-forward
B5: Net PPE | E5: ='BALANCE SHEET'!D5 -> 713.54 | F5: ='BALANCE SHEET'!E5 -> 777.63 | G5: ='BALANCE SHEET'!F5 -> 780.3 | H5: ='BALANCE SHEET'!G5 -> 773.94 | I5: =I7-I6 -> 755.44952 | J5: =J7-J6 -> 738.30701 | K5: =K7-K6 -> 731.58782 | L5: =L7-L6 -> 691.46201 | M5: =M7-M6 -> 649.56899
B6: Accumulated D&A | E6: ='INCOME STATEMENT'!D93 -> 291.3 | F6: ='INCOME STATEMENT'!E93 -> 342.93 | G6: ='INCOME STATEMENT'!F93 -> 398.77 | H6: ='INCOME STATEMENT'!G93 -> 476.37 | I6: =I32 -> 542.31714 | J6: =J32 -> 612.14522 | K6: =K32 -> 686.84847 | L6: =L32 -> 759.89972 | M6: =M32 -> 834.65776
B7: Closing Gross PP&E | E7: =SUM(E5:E6) -> 1004.84 | F7: =SUM(F5:F6) -> 1120.56 | G7: =SUM(G5:G6) -> 1179.07 | H7: =SUM(H5:H6) -> 1250.31 | I7: =I14 -> 1297.7667 | J7: =J14 -> 1350.4522 | K7: =K14 -> 1418.4363 | L7: =L14 -> 1451.3617 | M7: =M14 -> 1484.2267
B9: Opening PP&E | E9: 980.01 | F9: =E14 -> 1004.78 | G9: =F14 -> 1120.49 | H9: =G14 -> 1178.42 | I9: =H14 -> 1249.66 | J9: =I14 -> 1297.7667 | K9: =J14 -> 1350.4522 | L9: =K14 -> 1418.4363 | M9: =L14 -> 1451.3617
B11: Total CapEx | E11: 37.87 | F11: 121.34 | G11: 66.14 | H11: 78.08 | I11: 55 | J11: 60 | K11: 75 | L11: 40 | M11: 40 | O11: Total CapEx = Note 2 Total Tangibles gross block additions minus ROU additions (leasehold land + vehicles), yielding PP&E-only capitalisation. PP&E only: FY22 ₹37.87 Cr, FY23 ₹121.34 Cr, FY24 ₹66.14 Cr, FY25 ₹78.08 Cr. Forecast ₹55/60/75/40/40 Cr (FY26–30) derived from three anchors: (1) Note 36.1 FY25 AR: ₹1,392.41 Cr contracted but unspent CapEx confirms Nhava Yard spend committed for FY26–28. (2) FY25 AR Future Outlook: Dry Dock, Grand Assembly Area, 400T Goliath cranes entering active execution. (3) CWIP: FY25 additions ₹798.04 Cr (Note 3) represent procurement surge; FY26–28 CapEx reflects phased commissioning into gross block. Annual phasing: FY26–27 lower (civil/foundation work); FY28 peak (heavy equipment installation); FY29–30 step-down to steady-state post-commissioning. Total FY26–30 CapEx ₹270 Cr = ~19% of committed pipeline — conservative, as majority of Nhava Yard spend flows through CWIP before entering gross block. Maintenance vs. growth split removed — neither publicly disclosed; total CapEx is the only supportable assumption from public data
C12: 3Y Rolling Avg
B13: Disposals / Sale of PP&E | E13: 13.1 | F13: 5.63 | G13: 8.21 | H13: 6.84 | I13: =AVERAGE(F13:H13) -> 6.8933333 | J13: =AVERAGE(G13:I13) -> 7.3144444 | K13: =AVERAGE(H13:J13) -> 7.0159259 | L13: =AVERAGE(I13:K13) -> 7.0745679 | M13: =AVERAGE(J13:L13) -> 7.1349794 | O13: Actual: Disposals = Note 2 Total Tangibles deductions column (gross block). Source: Note 2, FY23 AR (FY22/FY23) and Note 2, FY25 AR (FY24/FY25). Values: FY22 ₹13.10 Cr, FY23 ₹5.63 Cr, FY24 ₹8.21 Cr, FY25 ₹6.84 Cr. FY22 elevated — likely batch retirement of aged workshop equipment coinciding with P15B/P17A ramp-up requiring facility upgrades; not structural. FY23–25 stable range ₹5.63–8.21 Cr reflecting routine retirement of end-of-life vehicles, computers, and loose tools per normal asset replacement cycle. Forecast: No disposal program, asset retirement schedule, or forward-looking commentary disclosed in any of the 5 ARs. MDL's core assets (dry docks, slipways, workshops, jointly-funded naval infrastructure) have long useful lives and are not subject to routine disposal — small annual disposal quantum reflects peripheral assets only. 3Y rolling avg (FY23–25) = ₹6.89 Cr applied flat throughout FY26–30 — FY22 outlier naturally excluded, tight historical range confirms stability, consistent with model-wide methodology.
B14: Closing Gross PP&E | E14: =E9+E11-E13 -> 1004.78 | F14: =F9+F11-F13 -> 1120.49 | G14: =G9+G11-G13 -> 1178.42 | H14: =H9+H11-H13 -> 1249.66 | I14: =I9+I11-I13 -> 1297.7667 | J14: =J9+J11-J13 -> 1350.4522 | K14: =K9+K11-K13 -> 1418.4363 | L14: =L9+L11-L13 -> 1451.3617 | M14: =M9+M11-M13 -> 1484.2267
B15: Error Check | E15: =ROUND(E7-E14,0) -> 0 | F15: =ROUND(F7-F14,0) -> 0 | G15: =ROUNDDOWN(G7-G14,0) -> 0 | H15: =ROUNDDOWN(H7-H14,0) -> 0 | I15: =ROUND(I7-I14,0) -> 0 | J15: =ROUND(J7-J14,0) -> 0 | K15: =ROUND(K7-K14,0) -> 0 | L15: =ROUND(L7-L14,0) -> 0 | M15: =ROUND(M7-M14,0) -> 0
B17: Opening CWIP | E17: =D21 -> 80.15 | F17: =E21 -> 86.94 | G17: =F21 -> 61.62 | H17: =G21 -> 68.24 | I17: =H21 -> 133.2 | J17: =I21 -> 147 | K17: =J21 -> 177 | L17: =K21 -> 217 | M17: =L21 -> 242
B18: CWIP Additions | E18: 241.12 | F18: 96.02 | G18: 76.86 | H18: 798.04 | I18: 138 | J18: 300 | K18: 400 | L18: 250 | M18: 150 | O18: Actual: CWIP Additions = Note 3 (Capital Work-in-Progress) expenditure during the period. Source: Note 3, FY21 AR (FY21); Note 3, FY23 AR (FY22/FY23); Note 3, FY24 AR (FY24); Note 3, FY25 AR (FY25). Values: FY22 ₹241.12 Cr, FY23 ₹96.02 Cr, FY24 ₹76.86 Cr, FY25 ₹798.04 Cr. FY25 spike to ₹798.04 Cr driven entirely by Nhava Yard expansion — one-time procurement surge confirmed by Note 3 FY25 AR completion schedule (Greenfield Shipyard, Repair Facility, Submarine Launch Facility, Caisson Gate as active items). Pre-Nhava baseline FY22-24 = ₹67-241 Cr range; no stable relationship with any operational metric (revenue, COGS, order book, cash) — CWIP Additions is a pure capital programme item driven by project timing, not operations. Forecast: FY26 ₹138 Cr — no new major programme starting; P75I contract signing confirmed delayed to FY27 per public disclosures (German Defence Minister Pistorius, April 2026); only existing programmes in execution (P17A, Coast Guard, Offshore). Value = 3Y avg FY22-24 pre-Nhava normal level (241.12 + 96.02 + 76.86) / 3 = ₹138 Cr — FY25 outlier excluded with documented cause. FY27 ₹300 Cr and FY28 ₹400 Cr — P75I contract signing FY27 triggers dedicated submarine infrastructure spend (assembly hall, pressure hull facility, dry dock modifications at Nhava Yard); peak spend FY28 as construction accelerates. FY29 ₹250 Cr — P75I infrastructure tapering, LPD/MCMV programmes potentially entering infrastructure phase per Q2 FY26 earnings call (RFP imminent). FY30 ₹150 Cr — normalizing toward steady state. FY27-30 quantum is directional only — exact infrastructure cost per programme not disclosed in any AR, earnings call, or public filing.
B19: Transfers to Commissioned Assets | E19: 234.33 | F19: 121.34 | G19: 66.71 | H19: 733.08 | I19: =0.9*I18 -> 124.2 | J19: =0.9*J18 -> 270 | K19: =0.9*K18 -> 360 | L19: =0.9*L18 -> 225 | M19: =0.9*M18 -> 135 | O19: Actual: Transfers = Note 3 capitalisation during the period (amounts transferred from CWIP to gross block upon commissioning). Source: same note references as CWIP Additions. Values: FY22 ₹234.33 Cr, FY23 ₹121.34 Cr, FY24 ₹66.71 Cr, FY25 ₹733.08 Cr. Reconciles to Note 2 gross block additions each year. Historical Transfers/Additions ratio: FY22 97%, FY24 87%, FY25 92% — FY23 excluded as outlier (transfers exceeded additions due to commissioning from prior CWIP accumulation). 3Y avg FY22/FY24/FY25 = 92%. Forecast: Transfers = 90% of CWIP Additions each year — anchored to historical 92% ratio (FY22/FY24/FY25 avg), rounded to 90% for conservatism. Remaining 10% stays in CWIP reflecting normal construction-in-progress at year end, consistent with MDL's historical CWIP cycle where majority of additions commission within the same financial year. FY26 ₹124 Cr, FY27 ₹270 Cr, FY28 ₹360 Cr, FY29 ₹225 Cr, FY30 ₹135 Cr. Note: Transfers ≠ Total CapEx — Total CapEx (gross block additions) includes both transfers from CWIP and direct purchases of small assets (vehicles, computers, loose tools) that bypass CWIP and are commissioned immediately. These are independent line items.
B20: Provision/Write-down | E20: 0 | F20: 0 | G20: 3.53 | H20: 0 | I20: 0 | J20: 0 | K20: 0 | L20: 0 | M20: 0 | O20: Provision/Write-down = Note 3 FY25 AR, provision for tangible assets within CWIP. FY24 only: ₹3.53 Cr (353 lakhs). All other years zero. Per Note 3 FY25 AR Previous Year Figures.
B21: Closing CWIP | D21: ='BALANCE SHEET'!C9 -> 80.15 | E21: =SUM(E17,E18,-E19,-E20) -> 86.94 | F21: =SUM(F17,F18,-F19,-F20) -> 61.62 | G21: =SUM(G17,G18,-G19,-G20) -> 68.24 | H21: =SUM(H17,H18,-H19,-H20) -> 133.2 | I21: =SUM(I17,I18,-I19,-I20) -> 147 | J21: =SUM(J17,J18,-J19,-J20) -> 177 | K21: =SUM(K17,K18,-K19,-K20) -> 217 | L21: =SUM(L17,L18,-L19,-L20) -> 242 | M21: =SUM(M17,M18,-M19,-M20) -> 257
B22: Error Check | E22: =ROUND(E21-'BALANCE SHEET'!D9,0) -> 0 | F22: =ROUND(F21-'BALANCE SHEET'!E9,0) -> 0 | G22: =ROUND(G21-'BALANCE SHEET'!F9,0) -> 0 | H22: =ROUND(H21-'BALANCE SHEET'!G9,0) -> 0 | I22: =ROUND(I21-'BALANCE SHEET'!H9,0) -> 0 | J22: =ROUND(J21-'BALANCE SHEET'!I9,0) -> 0 | K22: =ROUND(K21-'BALANCE SHEET'!J9,0) -> 0 | L22: =ROUND(L21-'BALANCE SHEET'!K9,0) -> 0 | M22: =ROUND(M21-'BALANCE SHEET'!L9,0) -> 0
B24: Opening Commissioned Assets | E24: =D7-D21 -> -80.15 | F24: =E7-E21 -> 917.9 | G24: =F7-F21 -> 1058.94 | H24: =G7-G21 -> 1110.83 | I24: =H7-H21 -> 1117.11 | J24: =I7-I21 -> 1150.7667 | K24: =J7-J21 -> 1173.4522 | L24: =K7-K21 -> 1201.4363 | M24: =L7-L21 -> 1209.3617
B25: Closing Commissioned Assets (Closing Gross Block − Closing CWIP) | E25: =E14-E21 -> 917.84 | F25: =F14-F21 -> 1058.87 | G25: =G14-G21 -> 1110.18 | H25: =H14-H21 -> 1116.46 | I25: =I14-I21 -> 1150.7667 | J25: =J14-J21 -> 1173.4522 | K25: =K14-K21 -> 1201.4363 | L25: =L14-L21 -> 1209.3617 | M25: =M14-M21 -> 1227.2267
B26: Average Commissioned Assets | E26: =AVERAGE(E24:E25) -> 418.845 | F26: =AVERAGE(F24:F25) -> 988.385 | G26: =AVERAGE(G24:G25) -> 1084.56 | H26: =AVERAGE(H24:H25) -> 1113.645 | I26: =AVERAGE(I24:I25) -> 1133.9383 | J26: =AVERAGE(J24:J25) -> 1162.1094 | K26: =AVERAGE(K24:K25) -> 1187.4443 | L26: =AVERAGE(L24:L25) -> 1205.399 | M26: =AVERAGE(M24:M25) -> 1218.2942
B27: D&A Rate (% of avg. Commissioned Assets) | C27: 3Y Rolling Avg | E27: =E30/E26 -> 0.15086727 | F27: =F30/F26 -> 0.057639483 | G27: =G30/G26 -> 0.05884414 | H27: =H30/H26 -> 0.075679413 | I27: =AVERAGE(F27:H27) -> 0.064054345 | J27: =AVERAGE(G27:I27) -> 0.066192633 | K27: =AVERAGE(H27:J27) -> 0.06864213 | L27: =AVERAGE(I27:K27) -> 0.066296369 | M27: =AVERAGE(J27:L27) -> 0.067043711 | O27: D&A Rate = PP&E D&A Charge / Average Commissioned Assets. FY23-24 stable at ~5.8% reflecting MDL's predominantly long-lived asset base (dry docks, slipways, workshops, jointly-funded naval infrastructure) depreciated on straight-line basis per Schedule II Companies Act 2013 (Note 2, FY25 AR). FY25 slight uptick to 7.57% driven by higher depreciation on newly commissioned Nhava Yard assets and building additions entering service. 3Y rolling avg (FY23-25) = 6.40% applied to FY26, rolling forward each year as new actuals enter the window. No structural change in depreciation policy disclosed in any AR — Schedule II straight-line methodology unchanged. Rolling avg preferred over flat rate as it naturally captures gradual shifts in asset mix as Nhava Yard infrastructure (longer-lived civil assets) increases as proportion of total gross block.
B29: Opening Accumulated D&A | E29: ='INCOME STATEMENT'!C93 -> 237.16 | F29: ='INCOME STATEMENT'!D93 -> 291.3 | G29: ='INCOME STATEMENT'!E93 -> 342.93 | H29: ='INCOME STATEMENT'!F93 -> 398.77 | I29: =H32 -> 476.37 | J29: =I32 -> 542.31714 | K29: =J32 -> 612.14522 | L29: =K32 -> 686.84847 | M29: =L32 -> 759.89972
B30: D&A Charge | E30: ='INCOME STATEMENT'!D31 -> 63.19 | F30: ='INCOME STATEMENT'!E31 -> 56.97 | G30: ='INCOME STATEMENT'!F31 -> 63.82 | H30: ='INCOME STATEMENT'!G31 -> 84.28 | I30: =I27*I26 -> 72.633677 | J30: =J27*J26 -> 76.923083 | K30: =K27*K26 -> 81.508704 | L30: =L27*L26 -> 79.913578 | M30: =M27*M26 -> 81.678967 | O30: D&A Charge = Note 2 Total Tangibles (A+B) 'For the period' column, representing tangibles-only D&A excluding intangibles amortisation. Source: FY23 AR (FY22/FY23), FY25 AR (FY24/FY25). Values: FY22 ₹68.69, FY23 ₹71.18, FY24 ₹77.76, FY25 ₹108.25 Cr.
